Workbook

Sheet 1. Configuration
B2: CARBELIM PRIVATE LIMITED
B5: AirForest™ Lab-Grade Photobioreactor — Product Configuration & Quotation Sheet
B6: Version 1.0 | Coimbatore, India | IIT Madras Research Park Incubatee
B8: Client / Organisation | D8: Dept. of Marine Biotechnology, Naval Materials Research Laboratory
B9: Contact Person | D9: Enter name
B10: Email / Phone | D10: Enter contact details
B11: Quotation Date | D11: DD-MMM-YYYY
B12: Quotation Ref # | D12: CBL-PBR-001
B13: Delivery Location | D13: Dept. of Marine Biotechnology, Naval Materials Research Laboratory, Ambernath (Maharashtra)
B15: CONFIGURATION OPTIONS — Tick / Highlight your selection in yellow cells
B16: Module | C16: Option A | D16: Option B | E16: Option C | F16: Notes
B17: Air Sensor Coverage | C17: Inlet Only | D17: Inlet + Outlet
B18: Connectivity | C18: WiFi Only (customer's router) | D18: WiFi + 4G SIM (standalone)
B19: IoT Dashboard | C19: None | D19: Cloud Dashboard (AWS-hosted)
B20: Electrical Supply | C20: 240V 50/60Hz | D20: 230 V / 50 Hz (Indian/International)
B22: PRICE SUMMARY (see Sheet 2 for full BOM)
B23: STRUCTURAL — Frame & Tank | F23: ='2. BOM & Pricing'!J9 -> 45750
B24: LIGHTING — LED Grow Lights (Side-Mounted) | F24: ='2. BOM & Pricing'!J14 -> 6500
B25: LIQUID SENSORS — pH, Turbidity, TDS, Temperature, Level | F25: ='2. BOM & Pricing'!J24 -> 21500
B26: AIR SENSORS — Option A | F26: ='2. BOM & Pricing'!J29 -> 16200
B27: ELECTRICAL — RCCB, MCBs, Relays, Wiring | F27: ='2. BOM & Pricing'!J41 -> 10500
B28: CONTROL SYSTEM — PLC + HMI (IDEC FT2J-7U) | F28: ='2. BOM & Pricing'!J45 -> 35000
B29: MISCELLANEOUS & CONSUMABLES | F29: ='2. BOM & Pricing'!J58 -> 8000
B30: Connectivity Module (as configured) | F30: =#REF! -> #REF!
B31: IoT Dashboard (annual, if selected) | F31: ='2. BOM & Pricing'!J54 -> 29000
B32: Subtotal (INR) | F32: =SUM(F23:F31) -> #REF!
B33: GST @ 18% | F33: =F32*0.18 -> #REF!
B34: GRAND TOTAL (INR) | F34: =F32+F33 -> #REF!
B36: Note: Prices are indicative (INR, ex-works Coimbatore). Taxes, freight, installation, and commissioning charged separately. Validity: 30 days from quotation date.

Sheet 2. BOM & Pricing
B2: CARBELIM PRIVATE LIMITED — AirForest™ PBR | Full Bill of Materials & Pricing
B4: Item # | C4: Category | D4: Component / Description | E4: Part Number / Model | F4: Qty | G4: Unit | H4: Unit Price (INR) | I4: Per Unit Margin | J4: Total (INR) | K4: Total Margin | L4: Remarks
B5: STRUCTURAL — Frame & Tank
B6: 1 | C6: STRUCTURAL | D6: SS304 Matte Frame | E6: Custom Fabricated | F6: 1 | G6: Set | H6: 12750 | I6: =H6 + (H6*110%) -> 26775 | J6: =F6*H6 -> 12750 | K6: =F6*I6 -> 26775 | L6: Includes base feet & mounting brackets
B7: 2 | C7: STRUCTURAL | D7: Acrylic Tank (50 L Capacity) | E7: Custom Fabricated | F7: 1 | G7: No. | H7: 30000 | I7: =H7 + (H7*110%) -> 63000 | J7: =F7*H7 -> 30000 | K7: =F7*I7 -> 63000 | L7: Silicone-sealed joints; drain port
B8: 3 | C8: STRUCTURAL | D8: Stainless Steel Hardware (bolts, nuts, standoffs) | E8: SS-304 Assorted | F8: 1 | G8: Lot | H8: 3000 | I8: =H8 + (H8*110%) -> 6300 | J8: =F8*H8 -> 3000 | K8: =F8*I8 -> 6300
B9: Subtotal — Frame & Tank | J9: =SUM(J6:J8) -> 45750 | K9: =SUM(K6:K8) -> 96075
B11: LIGHTING — LED Grow Lights (Side-Mounted)
B12: 5 | C12: LIGHTING | D12: Full-Spectrum LED Grow Strip (side panels, 4 sides) | E12: CARB LED equiv. | F12: 5 | G12: Strip | H12: 1000 | I12: =H12 + (H12*180%) -> 2800 | J12: =F12*H12 -> 5000 | K12: =F12*I12 -> 14000
B13: 6 | C13: LIGHTING | D13: LED Driver / Power Supply 24 V (for lighting) | E13: Power Supply | F13: 1 | G13: No. | H13: 1500 | I13: =H13 + (H13*180%) -> 4200 | J13: =F13*H13 -> 1500 | K13: =F13*I13 -> 4200 | L13: 100 W, 24 V / 4.2 A, DIN-rail
B14: Subtotal — LED Grow Lights (Side-Mounted) | J14: =SUM(J12:J13) -> 6500 | K14: =J14 + (J14*130%) -> 14950
B16: LIQUID SENSORS — pH, Turbidity, TDS, Temperature, Level
B17: 8 | C17: WATER SENSORS | D17: pH Sensor + Transmitter | E17: Carbelim CBPH01 | F17: 1 | G17: No. | H17: 8000 | I17: =H17 + (H17*180%) -> 22400 | J17: =F17*H17 -> 8000 | K17: =F17*I17 -> 22400 | L17: 0–14 pH, 0–60 °C; BNC probe; 0–5 V output
B18: 9 | C18: WATER SENSORS | D18: Turbidity Sensor (Basic) | E18: Carbelim CBTURB01 | F18: 1 | G18: No. | H18: 1600 | I18: =H18 + (H18*180%) -> 4480 | J18: =F18*H18 -> 1600 | K18: =F18*I18 -> 4480 | L18: 0–3000 NTU; 5 V DC; analog 0–4.5 V output
B19: 10 | C19: WATER SENSORS | D19: TDS Sensor (Basic) | E19: Carbelim CBTDS01 | F19: 1 | G19: No. | H19: 1400 | I19: =H19 + (H19*180%) -> 3920 | J19: =F19*H19 -> 1400 | K19: =F19*I19 -> 3920 | L19: 0–1000 ppm; 3.3–5.5 V; analog 0–2.3 V output
B20: 11 | C20: WATER SENSORS | D20: Water Temperature — PT100 RTD + Transmitter | E20: Carbelim CBPT100 | F20: 1 | G20: No. | H20: 1300 | I20: =H20 + (H20*180%) -> 3640 | J20: =F20*H20 -> 1300 | K20: =F20*I20 -> 3640 | L20: -10 to 100 °C; SPI interface to PLC/MCU
B21: 12 | C21: WATER SENSORS | D21: Liquid Level — Pressure Sensor | E21: Carbelim LEVEL01 | F21: 1 | G21: No. | H21: 2000 | I21: =H21 + (H21*180%) -> 5600 | J21: =F21*H21 -> 2000 | K21: =F21*I21 -> 5600 | L21: 4–20 mA output; submersible; stainless diaphragm
B22: 13 | C22: WATER SENSORS | D22: Signal Converter 0–5 V → 4–20 mA (DIN rail, ×3) | E22: Carbelim Signal multiplexer | F22: 1 | G22: No. | H22: 1200 | I22: =H22 + (H22*180%) -> 3360 | J22: =F22*H22 -> 1200 | K22: =F22*I22 -> 3360 | L22: For pH, turbidity, TDS long cable runs to PLC/PCB
B23: 14 | C23: Sensor Enclosure | D23: Enclosure for Wate Sensors | E23: Carbelim SENENCLO | F23: 1 | G23: No. | H23: 6000 | I23: =H13 + (H23*180%) -> 12300 | J23: 6000 | K23: =F23*I23 -> 12300 | L23: Enclsoure for Electrodes porbes
B24: Subtotal — pH, Turbidity, TDS, Temperature, Level | J24: =SUM(J17:J23) -> 21500 | K24: =SUM(K17:K23) -> 55700
B26: AIR SENSORS — Option A: Inlet Only
B27: 15 | C27: AIR SENSORS | D27: Multi-Gas Air Quality Module — INLET | E27: Carbelim CBZPHS01B | F27: 1 | G27: No. | H27: 15000 | I27: =H27 + (H27*220%) -> 48000 | J27: =F27*H27 -> 15000 | K27: =F27*I27 -> 48000 | L27: CO₂, CO, O₃, TVOC, HCHO, Temp, RH, PM2.5, PM10; RS-485 Modbus
B28: 16 | C28: AIR SENSORS | D28: Sensor Enclosure + Mounting Bracket (Inlet) | E28: Custom RS485 Hub | F28: 1 | G28: No. | H28: 1200 | I28: =H28 + (H28*130%) -> 2760 | J28: =F28*H28 -> 1200 | K28: =F28*I28 -> 2760 | L28: RS-485 cable entry
B29: Subtotal — Option A: Inlet Only | J29: =SUM(J27:J28) -> 16200 | K29: =SUM(K27:K28) -> 50760
B31: AIR SENSORS — Option B: Inlet + Outlet
B32: 17 | C32: AIR SENSORS | D32: Multi-Gas Air Quality Module — OUTLET | E32: Carbelim CBZPHS01B | F32: 2 | G32: No. | H32: 15000 | I32: =H32 + (H32*220%) -> 48000 | J32: =F32*H32 -> 30000 | K32: =F32*I32 -> 96000 | L32: CO₂, CO, O₃, TVOC, HCHO, Temp, RH, PM2.5, PM10; RS-485 Modbus
B33: 18 | C33: AIR SENSORS | D33: Sensor Enclosure + Mounting Bracket (Outlet) | E33: Custom RS485 Hub | F33: 1 | G33: No. | H33: 1200 | I33: =H33 + (H33*130%) -> 2760 | J33: =F33*H33 -> 1200 | K33: =F33*I33 -> 2760 | L33: RS-485 cable entry
B34: Subtotal — Option B: Inlet + Outlet (additional to D-A) | J34: =SUM(J32:J33) -> 31200 | K34: =SUM(K32:K33) -> 98760
B36: ELECTRICAL — RCCB, MCBs, Relays, Wiring, Terminals
B37: 19 | C37: Protection | D37: Circuit Breakers (Main RCCB & Branch MCBs) | E37: Main RCCB & Branch MCBs | F37: 1 | G37: Lot | H37: 2800 | I37: =H37 + (H37*350%) -> 12600 | J37: =F37*H37 -> 2800 | K37: =F37*I37 -> 12600 | L37: Main earth-leakage and circuit overload protection
B38: 20 | C38: Air Compression unit | D38: Carbelim CAQ-013 | E38: 4 Watts, 2*4LPM Aeration | F38: 1 | G38: No. | H38: 600 | I38: =H38 + (H38*350%) -> 2700 | J38: =F38*H38 -> 600 | K38: =F38*I38 -> 2700 | L38: Aeration
B39: 21 | C39: Intake Auxiliary fan | D39: Carbelim CIAF | E39: 12V DC/ 240V AC | F39: 1 | G39: No. | H39: 600 | I39: =H39 + (H39*350%) -> 2700 | J39: =F39*H39 -> 600 | K39: =F39*I39 -> 2700
B40: 22 | C40: Enclosure, Connection and Control | D40: Waterproof Switchboard, Wiring Kit (Cables, Terminals, DIN Rails, Ducts), Relays (Solid-State & DIN-Rail), Power Supplies (24V/12V SMPS) & Power Inlet | E40: Waterproof Switchboard, Cables, Terminals, DIN Rails, Ducts, SSR and Relays, Cables, Terminals, DIN Rails, Ducts, SMPS (24V/12V SMPS) | F40: 1 | G40: No. | H40: 6500 | I40: =H40 + (H40*350%) -> 29250 | J40: =F40*H40 -> 6500 | K40: =F40*I40 -> 29250 | L40: Safe housing for all electrical components, Power routing, sensor wiring, and component mounting
B41: Subtotal — RCCB, MCBs, Relays, Wiring, Terminals | J41: =SUM(J37:J40) -> 10500 | K41: =SUM(K37:K40) -> 47250
B43: CONTROL SYSTEM — PLC + HMI (IDEC FT2J-7U)
B44: 23 | C44: CONTROL SYSTEM | D44: HMI Logic Control Board | E44: Carbelim IDEC PLC (FT2J-7U22RAF-B) | F44: 1 | G44: No. | H44: 35000 | I44: =H44 + (H44*360%) -> 161000 | J44: =F44*H44 -> 35000 | K44: =F44*I44 -> 161000 | L44: Analog DIgital Input, 24 V DC
B45: Subtotal — HMI + PLC (IDEC FT2J-7U) | J45: =SUM(J44) -> 35000 | K45: =SUM(K44) -> 161000
B47: CONNECTIVITY — Option B: WiFi + 4G SIM (additional)
B48: 24 | C48: CONNECTIVITY | D48: 4G LTE + WiFi Module | E48: SIM Card based Router for WiFi/ Ethernet | F48: 1 | G48: No. | H48: 1500 | I48: =H48 + (H48*130%) -> 3450 | J48: =F48*H48 -> 1500 | K48: =F48*I48 -> 3450 | L48: LTE Cat-4; dual SIM;
B49: Subtotal — Option B: WiFi + 4G SIM (additional) | J49: =SUM(J48) -> 1500 | K49: =SUM(K48) -> 3450
...

Sheet 3. Technical Specs
B2: CARBELIM AirForest™ — Lab-Grade PBR | Technical Specifications
B4: Parameter | C4: Specification / Value | D4: Notes
B5: 1. MECHANICAL & STRUCTURAL
B6: Overall Dimensions (W × D × H) | C6: TBD | D6: Varies with tank volume
B7: Frame Material | C7: MS Square Tube
B8: Tank Material | C8: Cast Acrylic
B9: Tank Volume (nominal) | C9: 50 litres
B10: Operating Weight (filled) | C10: TBD | D10: Incl. frame, tank, electronics
B11: Ingress Protection — Panel | C11: Electrical enclosure
B13: 2. LIGHTING
B14: Light Type | C14: Full-Spectrum LED, side-mounted
B15: Number of Panels | C15: 4 sides (full perimeter)
B16: Power per Strip | C16: TBD | D16: TBD
B17: Control | C17: Relay based Control | D17: 0–10 V analog output
B18: Voltage | C18: 24 V DC | D18: Powered by Power Supply
B20: 3. LIQUID SENSING
B21: pH Range | C21: 0–14 pH | D21: Carbelim CBPH01; ±0.1 pH accuracy
B22: Turbidity Range (Basic) | C22: 0–3000 NTU | D22: Carbelim CBTURB01; ±5% FS
B23: TDS Range (Basic) | C23: 0–1000 ppm | D23: Carbelim CBTDS01; ±10% FS
B24: Water Temperature | C24: -10 to 100 °C | D24: Carbelim CBPT100; ±0.5 °C
B25: Liquid Level | C25: 0–500 mm (hydrostatic) | D25: Carbelim LEVEL01 4-20ma; ±1% FS
B26: DO Sensor | C26: 0 to 20.0 ppm (mg/L) | D26: Carbelim DOSensor ±0.2 ppm to ±1 count
B28: 4. AIR SENSING (Carbelim CBZPHS01B)
B29: Parameters Measured | C29: CO₂, CO, O₃, TVOC, HCHO, Temp, RH, PM2.5, PM10 | D29: 11 Modbus registers
B30: CO₂ Range | C30: 400–5000 ppm | D30: ±50 ppm or ±5% of reading
B31: PM2.5 / PM10 Range | C31: 0–999 µg/m³ | D31: Laser scattering method
B32: Temperature (air) | C32: -10 to 50 °C | D32: ±0.5 °C
B33: Relative Humidity | C33: 0–100% RH | D33: ±3% RH
B34: Communication | C34: RS-485 Modbus RTU, 9600 baud | D34: FC03; addresses 0–10
B35: Sensor Positions | C35: Inlet (Option A) or Inlet + Outlet (Option B) | D35: Option B adds 1 ZPHS01B
B37: 5. CONTROL SYSTEM
B38: PCB / HMI + PLC | C38: IDEC FT2J-7U/ Carbelim PCB | D38: 7" TFT touch; RS-485; Ethernet
B40: 6. CONNECTIVITY & IoT
B41: WiFi Option | C41: IEEE 802.11 b/g/n; 2.4 GHz | D41: Connect to existing LAN router
B42: SIM Option (add-on) | C42: 4G LTE Cat-4 | D42: Standalone; nano SIM
B43: Protocol | C43: MQTT over TLS (AWS IoT Core) | D43: QoS 1; retained messages
B44: Cloud Backend | C44: AWS IoT Core + DynamoDB + S3 | D44: Serverless; scales to fleet
B45: Dashboard | C45: Web-based (responsive); WebSocket real-time | D45: Mobile + desktop; no app install
B46: Data Retention | C46: Hot: 30 days DynamoDB; Cold: 2 years S3 | D46: Tiered TTL strategy
B48: 7. ELECTRICAL
...
